
try{
    console.log(a+b);
    // throw new ReferenceError();
} catch(err){
     console.log("there was an  error");
     console.log("error saved in error log");
}

console.log("code goes on");
